<?xml version="1.0" ?>
<!-- =================================================================================== -->
<!-- |    This document was autogenerated by xacro from /home/gauss/projects/personal_ws/src/parallel_2f_gripper/urdf/gripper_pybullet.xacro | -->
<!-- |    EDITING THIS FILE BY HAND IS NOT RECOMMENDED                                 | -->
<!-- =================================================================================== -->
<!--
Copyright (c) 2022, JRL-CARI CNR-STIIMA/UNIBS
Manuel Beschi manuel.beschi@unibs.it
All rights reserved.

Redistribution and use in source and binary forms, with or without
modification, are permitted provided that the following conditions are met:
    * Redistributions of source code must retain the above copyright
      notice, this list of conditions and the following disclaimer.
    * Redistributions in binary form must reproduce the above copyright
      notice, this list of conditions and the following disclaimer in the
      documentation and/or other materials provided with the distribution.
    * Neither the name of the <organization> nor the
      names of its contributors may be used to endorse or promote products
      derived from this software without specific prior written permission.

THIS SOFTWARE IS PROVIDED BY THE COPYRIGHT HOLDERS AND CONTRIBUTORS "AS IS" AND
ANY EXPRESS OR IMPLIED WARRANTIES, INCLUDING, BUT NOT LIMITED TO, THE IMPLIED
WARRANTIES OF MERCHANTABILITY AND FITNESS FOR A PARTICULAR PURPOSE ARE
DISCLAIMED. IN NO EVENT SHALL <COPYRIGHT HOLDER> BE LIABLE FOR ANY
DIRECT, INDIRECT, INCIDENTAL, SPECIAL, EXEMPLARY, OR CONSEQUENTIAL DAMAGES
(INCLUDING, BUT NOT LIMITED TO, PROCUREMENT OF SUBSTITUTE GOODS OR SERVICES;
LOSS OF USE, DATA, OR PROFITS; OR BUSINESS INTERRUPTION) HOWEVER CAUSED AND
ON ANY THEORY OF LIABILITY, WHETHER IN CONTRACT, STRICT LIABILITY, OR TORT
(INCLUDING NEGLIGENCE OR OTHERWISE) ARISING IN ANY WAY OUT OF THE USE OF THIS
SOFTWARE, EVEN IF ADVISED OF THE POSSIBILITY OF SUCH DAMAGE.
-->
<robot name="parallel_gripper">
  <link name="gripper_base">
    <inertial>
      <origin rpy="0 0 0" xyz="0 0 0"/>
      <mass value="0.2"/>
      <inertia ixx="0.001" ixy="0.0" ixz="0.0" iyy="0.001" iyz="0.0" izz="0.001"/>
    </inertial>
    <visual>
      <origin rpy="0 0 0" xyz="0 0 0.025"/>
      <geometry>
        <box size="0.1 0.05 0.05"/>
      </geometry>
      <material name="aluminium">
        <color rgba="0.515625 0.52734375 0.53515625 1"/>
      </material>
    </visual>
    <collision>
      <origin rpy="0 0 0" xyz="0 0 0.025"/>
      <geometry>
        <box size="0.1 0.05 0.05"/>
      </geometry>
      <material name="aluminium">
        <color rgba="0.515625 0.52734375 0.53515625 1"/>
      </material>
    </collision>
  </link>
  <link name="right_crank">
    <inertial>
      <origin rpy="0 0 0" xyz="0 0 0"/>
      <mass value="0.2"/>
      <inertia ixx="0.001" ixy="0.0" ixz="0.0" iyy="0.001" iyz="0.0" izz="0.001"/>
    </inertial>
    <visual>
      <origin rpy="0 0 0" xyz="0 0 0.035"/>
      <geometry>
        <box size="0.01 0.05 0.07"/>
      </geometry>
      <material name="aluminium">
        <color rgba="0.515625 0.52734375 0.53515625 1"/>
      </material>
    </visual>
    <collision>
      <origin rpy="0 0 0" xyz="0 0 0.035"/>
      <geometry>
        <box size="0.01 0.05 0.07"/>
      </geometry>
      <material name="aluminium">
        <color rgba="0.515625 0.52734375 0.53515625 1"/>
      </material>
    </collision>
  </link>
  <link name="right_external_crank">
    <inertial>
      <origin rpy="0 0 0" xyz="0 0 0"/>
      <mass value="0.2"/>
      <inertia ixx="0.001" ixy="0.0" ixz="0.0" iyy="0.001" iyz="0.0" izz="0.001"/>
    </inertial>
    <visual>
      <origin rpy="0 0 0" xyz="0 0 0.035"/>
      <geometry>
        <box size="0.01 0.05 0.07"/>
      </geometry>
      <material name="aluminium">
        <color rgba="0.515625 0.52734375 0.53515625 1"/>
      </material>
    </visual>
    <collision>
      <origin rpy="0 0 0" xyz="0 0 0.035"/>
      <geometry>
        <box size="0.01 0.05 0.07"/>
      </geometry>
      <material name="aluminium">
        <color rgba="0.515625 0.52734375 0.53515625 1"/>
      </material>
    </collision>
  </link>
  <link name="right_rod">
    <inertial>
      <origin rpy="0 0 0" xyz="0 0 0"/>
      <mass value="0.2"/>
      <inertia ixx="0.001" ixy="0.0" ixz="0.0" iyy="0.001" iyz="0.0" izz="0.001"/>
    </inertial>
    <visual>
      <origin rpy="0 0 0" xyz="0 0 0.025"/>
      <geometry>
        <box size="0.01 0.05 0.05"/>
      </geometry>
      <material name="aluminium">
        <color rgba="0.515625 0.52734375 0.53515625 1"/>
      </material>
    </visual>
    <collision>
      <origin rpy="0 0 0" xyz="0 0 0.025"/>
      <geometry>
        <box size="0.01 0.05 0.05"/>
      </geometry>
      <material name="aluminium">
        <color rgba="0.515625 0.52734375 0.53515625 1"/>
      </material>
    </collision>
  </link>
  <link name="right_base_rod">
    <inertial>
      <origin rpy="0 0 0" xyz="0 0 0"/>
      <mass value="0.2"/>
      <inertia ixx="0.001" ixy="0.0" ixz="0.0" iyy="0.001" iyz="0.0" izz="0.001"/>
    </inertial>
    <visual>
      <origin rpy="0 0 0" xyz="0 0 0.025"/>
      <geometry>
        <box size="0.01 0.05 0.05"/>
      </geometry>
      <material name="aluminium">
        <color rgba="0.515625 0.52734375 0.53515625 1"/>
      </material>
    </visual>
    <collision>
      <origin rpy="0 0 0" xyz="0 0 0.025"/>
      <geometry>
        <box size="0.01 0.05 0.05"/>
      </geometry>
      <material name="aluminium">
        <color rgba="0.515625 0.52734375 0.53515625 1"/>
      </material>
    </collision>
  </link>
  <link name="right_phalanx">
    <inertial>
      <origin rpy="0 0 0" xyz="0 0 0"/>
      <mass value="0.2"/>
      <inertia ixx="0.001" ixy="0.0" ixz="0.0" iyy="0.001" iyz="0.0" izz="0.001"/>
    </inertial>
    <visual>
      <origin rpy="0 0 0" xyz="0 0 0.025"/>
      <geometry>
        <box size="0.01 0.05 0.05"/>
      </geometry>
      <material name="aluminium">
        <color rgba="0.515625 0.52734375 0.53515625 1"/>
      </material>
    </visual>
    <collision>
      <origin rpy="0 0 0" xyz="0 0 0.025"/>
      <geometry>
        <box size="0.01 0.05 0.05"/>
      </geometry>
      <material name="aluminium">
        <color rgba="0.515625 0.52734375 0.53515625 1"/>
      </material>
    </collision>
  </link>
  <joint name="right_finger_joint" type="revolute">
    <origin rpy="0 0 0" xyz="0.055 0 0.05"/>
    <parent link="gripper_base"/>
    <child link="right_crank"/>
    <axis xyz="0 1 0"/>
    <limit effort="5" lower="-0.7956029534845354" upper="1" velocity="5.0"/>
  </joint>
  <joint name="right_joint_2_5" type="fixed">
    <origin rpy="0 -1.5707963267948966 0" xyz="0 0 0"/>
    <parent link="right_rod"/>
    <child link="right_phalanx"/>
    <axis xyz="0 1 0"/>
  </joint>
  <joint name="right_joint_1_2" type="revolute">
    <origin rpy="0 1.5707963267948966 0" xyz="0 0 0.07"/>
    <parent link="right_crank"/>
    <child link="right_rod"/>
    <axis xyz="0 1 0"/>
    <limit effort="10" lower="-3.141592653589793" upper="3.141592653589793" velocity="2.0"/>
    <mimic joint="right_finger_joint" multiplier="-1" offset="0"/>
  </joint>
  <joint name="right_joint_2_3" type="revolute">
    <origin rpy="0 1.5707963267948966 0" xyz="0 0 0.05"/>
    <parent link="right_rod"/>
    <child link="right_external_crank"/>
    <axis xyz="0 1 0"/>
    <limit effort="10" lower="-3.141592653589793" upper="3.141592653589793" velocity="2.0"/>
    <mimic joint="right_finger_joint" multiplier="1" offset="0"/>
  </joint>
  <joint name="right_joint_3_4" type="revolute">
    <origin rpy="0 1.5707963267948966 0" xyz="0 0 0.07"/>
    <parent link="right_external_crank"/>
    <child link="right_base_rod"/>
    <axis xyz="0 1 0"/>
    <limit effort="10" lower="-3.141592653589793" upper="3.141592653589793" velocity="2.0"/>
    <mimic joint="right_finger_joint" multiplier="-1" offset="0"/>
  </joint>
  <!-- Add if to include this link only for rviz  -->
  <!-- <link name="${prefix}tip"/>
    <joint name="${prefix}tip_joint" type="fixed">
      <origin xyz="${-0.5*link_width} 0 ${phalanx_length}" rpy="0 0 0"/>
      <parent link="${prefix}phalanx" />
      <child link="${prefix}tip" />
    </joint> -->
  <!-- <gazebo>
      <joint name="${prefix}joint_4_1" type="revolute">
        <parent>${prefix}base_rod</parent>
        <child>${prefix}crank</child>
        <pose relative_to="${prefix}base_rod">0 0 ${rod_length}   0 ${pi/2} 0</pose>
        <axis>
          <xyz>0 1 0</xyz>
        </axis>
      </joint>

      <joint name="${prefix}joint_0_4" type="revolute">
        <parent>${base_name}</parent>
        <child>${prefix}base_rod</child>
        <pose relative_to="${base_name}">${(0.5*(base_x+link_width)+rod_length)*cos(rot_z)} 0 ${base_z} 0 0 ${rot_z}</pose>
        <axis>
          <xyz>0 1 0</xyz>
        </axis>
      </joint>
    </gazebo>

    <gazebo reference="${prefix}phalanx">
      <self_collide>1</self_collide>
      <kp>100000</kp>
      <kd>200</kd>
      <mu1>2</mu1>
      <mu2>2</mu2>
    </gazebo> -->
  <link name="left_crank">
    <inertial>
      <origin rpy="0 0 0" xyz="0 0 0"/>
      <mass value="0.2"/>
      <inertia ixx="0.001" ixy="0.0" ixz="0.0" iyy="0.001" iyz="0.0" izz="0.001"/>
    </inertial>
    <visual>
      <origin rpy="0 0 0" xyz="0 0 0.035"/>
      <geometry>
        <box size="0.01 0.05 0.07"/>
      </geometry>
      <material name="aluminium">
        <color rgba="0.515625 0.52734375 0.53515625 1"/>
      </material>
    </visual>
    <collision>
      <origin rpy="0 0 0" xyz="0 0 0.035"/>
      <geometry>
        <box size="0.01 0.05 0.07"/>
      </geometry>
      <material name="aluminium">
        <color rgba="0.515625 0.52734375 0.53515625 1"/>
      </material>
    </collision>
  </link>
  <link name="left_external_crank">
    <inertial>
      <origin rpy="0 0 0" xyz="0 0 0"/>
      <mass value="0.2"/>
      <inertia ixx="0.001" ixy="0.0" ixz="0.0" iyy="0.001" iyz="0.0" izz="0.001"/>
    </inertial>
    <visual>
      <origin rpy="0 0 0" xyz="0 0 0.035"/>
      <geometry>
        <box size="0.01 0.05 0.07"/>
      </geometry>
      <material name="aluminium">
        <color rgba="0.515625 0.52734375 0.53515625 1"/>
      </material>
    </visual>
    <collision>
      <origin rpy="0 0 0" xyz="0 0 0.035"/>
      <geometry>
        <box size="0.01 0.05 0.07"/>
      </geometry>
      <material name="aluminium">
        <color rgba="0.515625 0.52734375 0.53515625 1"/>
      </material>
    </collision>
  </link>
  <link name="left_rod">
    <inertial>
      <origin rpy="0 0 0" xyz="0 0 0"/>
      <mass value="0.2"/>
      <inertia ixx="0.001" ixy="0.0" ixz="0.0" iyy="0.001" iyz="0.0" izz="0.001"/>
    </inertial>
    <visual>
      <origin rpy="0 0 0" xyz="0 0 0.025"/>
      <geometry>
        <box size="0.01 0.05 0.05"/>
      </geometry>
      <material name="aluminium">
        <color rgba="0.515625 0.52734375 0.53515625 1"/>
      </material>
    </visual>
    <collision>
      <origin rpy="0 0 0" xyz="0 0 0.025"/>
      <geometry>
        <box size="0.01 0.05 0.05"/>
      </geometry>
      <material name="aluminium">
        <color rgba="0.515625 0.52734375 0.53515625 1"/>
      </material>
    </collision>
  </link>
  <link name="left_base_rod">
    <inertial>
      <origin rpy="0 0 0" xyz="0 0 0"/>
      <mass value="0.2"/>
      <inertia ixx="0.001" ixy="0.0" ixz="0.0" iyy="0.001" iyz="0.0" izz="0.001"/>
    </inertial>
    <visual>
      <origin rpy="0 0 0" xyz="0 0 0.025"/>
      <geometry>
        <box size="0.01 0.05 0.05"/>
      </geometry>
      <material name="aluminium">
        <color rgba="0.515625 0.52734375 0.53515625 1"/>
      </material>
    </visual>
    <collision>
      <origin rpy="0 0 0" xyz="0 0 0.025"/>
      <geometry>
        <box size="0.01 0.05 0.05"/>
      </geometry>
      <material name="aluminium">
        <color rgba="0.515625 0.52734375 0.53515625 1"/>
      </material>
    </collision>
  </link>
  <link name="left_phalanx">
    <inertial>
      <origin rpy="0 0 0" xyz="0 0 0"/>
      <mass value="0.2"/>
      <inertia ixx="0.001" ixy="0.0" ixz="0.0" iyy="0.001" iyz="0.0" izz="0.001"/>
    </inertial>
    <visual>
      <origin rpy="0 0 0" xyz="0 0 0.025"/>
      <geometry>
        <box size="0.01 0.05 0.05"/>
      </geometry>
      <material name="aluminium">
        <color rgba="0.515625 0.52734375 0.53515625 1"/>
      </material>
    </visual>
    <collision>
      <origin rpy="0 0 0" xyz="0 0 0.025"/>
      <geometry>
        <box size="0.01 0.05 0.05"/>
      </geometry>
      <material name="aluminium">
        <color rgba="0.515625 0.52734375 0.53515625 1"/>
      </material>
    </collision>
  </link>
  <joint name="left_finger_joint" type="revolute">
    <origin rpy="0 0 3.141592653589793" xyz="-0.055 0 0.05"/>
    <parent link="gripper_base"/>
    <child link="left_crank"/>
    <axis xyz="0 1 0"/>
    <limit effort="5" lower="-0.7956029534845354" upper="1" velocity="5.0"/>
    <mimic joint="right_finger_joint" multiplier="1" offset="0"/>
  </joint>
  <joint name="left_joint_2_5" type="fixed">
    <origin rpy="0 -1.5707963267948966 0" xyz="0 0 0"/>
    <parent link="left_rod"/>
    <child link="left_phalanx"/>
    <axis xyz="0 1 0"/>
  </joint>
  <joint name="left_joint_1_2" type="revolute">
    <origin rpy="0 1.5707963267948966 0" xyz="0 0 0.07"/>
    <parent link="left_crank"/>
    <child link="left_rod"/>
    <axis xyz="0 1 0"/>
    <limit effort="10" lower="-3.141592653589793" upper="3.141592653589793" velocity="2.0"/>
    <mimic joint="left_finger_joint" multiplier="-1" offset="0"/>
  </joint>
  <joint name="left_joint_2_3" type="revolute">
    <origin rpy="0 1.5707963267948966 0" xyz="0 0 0.05"/>
    <parent link="left_rod"/>
    <child link="left_external_crank"/>
    <axis xyz="0 1 0"/>
    <limit effort="10" lower="-3.141592653589793" upper="3.141592653589793" velocity="2.0"/>
    <mimic joint="left_finger_joint" multiplier="1" offset="0"/>
  </joint>
  <joint name="left_joint_3_4" type="revolute">
    <origin rpy="0 1.5707963267948966 0" xyz="0 0 0.07"/>
    <parent link="left_external_crank"/>
    <child link="left_base_rod"/>
    <axis xyz="0 1 0"/>
    <limit effort="10" lower="-3.141592653589793" upper="3.141592653589793" velocity="2.0"/>
    <mimic joint="left_finger_joint" multiplier="-1" offset="0"/>
  </joint>
  <!-- Add if to include this link only for rviz  -->
  <!-- <link name="${prefix}tip"/>
    <joint name="${prefix}tip_joint" type="fixed">
      <origin xyz="${-0.5*link_width} 0 ${phalanx_length}" rpy="0 0 0"/>
      <parent link="${prefix}phalanx" />
      <child link="${prefix}tip" />
    </joint> -->
  <!-- <gazebo>
      <joint name="${prefix}joint_4_1" type="revolute">
        <parent>${prefix}base_rod</parent>
        <child>${prefix}crank</child>
        <pose relative_to="${prefix}base_rod">0 0 ${rod_length}   0 ${pi/2} 0</pose>
        <axis>
          <xyz>0 1 0</xyz>
        </axis>
      </joint>

      <joint name="${prefix}joint_0_4" type="revolute">
        <parent>${base_name}</parent>
        <child>${prefix}base_rod</child>
        <pose relative_to="${base_name}">${(0.5*(base_x+link_width)+rod_length)*cos(rot_z)} 0 ${base_z} 0 0 ${rot_z}</pose>
        <axis>
          <xyz>0 1 0</xyz>
        </axis>
      </joint>
    </gazebo>

    <gazebo reference="${prefix}phalanx">
      <self_collide>1</self_collide>
      <kp>100000</kp>
      <kd>200</kd>
      <mu1>2</mu1>
      <mu2>2</mu2>
    </gazebo> -->
  <transmission name="right_finger_joint_trans">
    <type>transmission_interface/SimpleTransmission</type>
    <joint name="right_finger_joint">
      <hardwareInterface>hardware_interface/EffortJointInterface</hardwareInterface>
    </joint>
    <actuator name="right_finger_joint_motor">
      <mechanicalReduction>1</mechanicalReduction>
    </actuator>
  </transmission>
  <transmission name="left_finger_joint_trans">
    <type>transmission_interface/SimpleTransmission</type>
    <joint name="left_finger_joint">
      <hardwareInterface>hardware_interface/EffortJointInterface</hardwareInterface>
    </joint>
    <actuator name="left_finger_joint_motor">
      <mechanicalReduction>1</mechanicalReduction>
    </actuator>
  </transmission>
</robot>

